Workbook

Sheet 📋 Cover
A2: OxyPC Inventory Management System
A3: User Acceptance Test (UAT) — Test Case Repository
A4: Version 1.0 | March 2026 | Confidential — Internal Use Only
A6: Document Information
A7: Document Title | C7: OxyPC IMS — UAT Test Cases
A8: Version | C8: 1.0
A9: Date | C9: March 20, 2026
A10: Status | C10: DRAFT
A11: Prepared By | C11: OxyPC QA Team
A12: System | C12: http://<server-ip>:8000
A13: Test Environment | C13: Local development server with dummy data seeded
A14: Admin Credentials | C14: Username: admin | Password: Admin@1234
A15: Test Data | C15: Run seed_dummy_data.py to populate test records
A17: Test Module Index
A18: Module ID | B18: Module Name | C18: Coverage Description | D18: Sheet
A19: TC-AUTH | B19: 01 — Authentication | C19: Login, logout, JWT refresh, role enforcement | D19: 01 — Authentication
A20: TC-LOT | B20: 02 — Lot Management | C20: Create lots, lot P&L, bulk upload | D20: 02 — Lot Management
A21: TC-IQC | B21: 03 — IQC | C21: Device registration, barcode scan, all 23 fields | D21: 03 — IQC
A22: TC-STOCK | B22: 04 — Stock In | C22: Move to stock, location assignment | D22: 04 — Stock In
A23: TC-L1 | B23: 05 — L1 Repair | C23: Start job, log parts, complete, advance | D23: 05 — L1 Repair
A24: TC-L2 | B24: 06 — L2 Repair | C24: Start job, log parts, complete, advance | D24: 06 — L2 Repair
A25: TC-L3 | B25: 07 — L3 Repair | C25: Start job, log parts, complete, advance | D25: 07 — L3 Repair
A26: TC-QC | B26: 08 — QC Check | C26: Pass, fail, scrap, grade assignment | D26: 08 — QC Check
A27: TC-COS | B27: 09 — Cosmetic Pipeline | C27: All 6 stages: Cleaning → Final QC | D27: 09 — Cosmetic Pipeline
A28: TC-SALE | B28: 10 — Sales | C28: Create sale, payment modes, invoice | D28: 10 — Sales
A29: TC-RET | B29: 11 — Returns | C29: Process return, re-routing device | D29: 11 — Returns
... A37: TC-SEC | B37: 19 — Security & Access | C37: Role enforcement, unauthorized access | D37: 19 — Security & Access

Sheet 🧪 All Test Cases
A1: TC ID | B1: Module | C1: Priority | D1: Test Type | E1: Test Scenario | F1: Pre-Conditions | G1: Test Steps | H1: Test Data | I1: Expected Result | J1: Actual Result | K1: Pass / Fail | L1: Remarks
A2: TC-AUTH-001 | B2: Authentication | C2: Critical | D2: Positive | E2: Valid admin login | F2: Admin user exists; server running | G2: 1. Navigate to http://<server>/ 2. Enter username: admin 3. Enter password: Admin@1234 4. Click Login | H2: user: admin | pwd: Admin@1234 | I2: Dashboard loads; sidebar shows all modules; user name visible in header
A3: TC-AUTH-002 | B3: Authentication | C3: Critical | D3: Negative | E3: Invalid password login | F3: Server running | G3: 1. Navigate to login page 2. Enter username: admin 3. Enter incorrect password: wrong123 4. Click Login | H3: user: admin | pwd: wrong123 | I3: Error message: 'Invalid credentials'; user stays on login page; no session created
A4: TC-AUTH-003 | B4: Authentication | C4: Critical | D4: Negative | E4: Non-existent user login | F4: Server running | G4: 1. Navigate to login page 2. Enter username: nobody 3. Enter any password 4. Click Login | H4: user: nobody | pwd: anything | I4: Error message shown; no access granted
A5: TC-AUTH-004 | B5: Authentication | C5: High | D5: Negative | E5: Deactivated user cannot login | F5: User 'testuser' exists with status=inactive | G5: 1. Admin deactivates a user 2. Attempt login with that user's credentials | H5: Deactivated user credentials | I5: Login rejected with 'Account inactive' or similar message
A6: TC-AUTH-005 | B6: Authentication | C6: High | D6: Positive | E6: Logout clears session | F6: User is logged in | G6: 1. Login as any user 2. Click Logout 3. Press browser Back button 4. Try to access /dashboard | H6: Any valid user | I6: User is redirected to login page; session cookie cleared
A7: TC-AUTH-006 | B7: Authentication | C7: High | D7: Security | E7: Role-based page access — Sales cannot access Admin | F7: User with Sales role is logged in | G7: 1. Login as salesexec 2. Manually navigate to http://<server>/admin | H7: user: salesexec | pwd: Test@1234 | I7: 403 Forbidden or redirect to login page; Admin module not accessible
A8: TC-AUTH-007 | B8: Authentication | C8: High | D8: Security | E8: Role-based access — IQC cannot access Sales | F8: User with IQC role is logged in | G8: 1. Login as iqc1 2. Navigate to /sales | H8: user: iqc1 | pwd: Test@1234 | I8: 403 error or redirect; IQC user cannot access Sales module
A9: TC-LOT-001 | B9: Lot Management | C9: Critical | D9: Positive | E9: Create new lot | F9: Admin or Inventory Manager logged in | G9: 1. Go to Lots → New Lot 2. Fill all fields 3. Click Save | H9: Lot#: LOT-UAT-001 | Supplier: ABC Traders | Price: 85000 | Qty: 10 | Date: 2026-03-15 | Inv#: INV-UAT-001 | I9: Lot created; appears in lot list with correct details; lot count increments by 1
A10: TC-LOT-002 | B10: Lot Management | C10: High | D10: Negative | E10: Duplicate lot number rejected | F10: Lot LOT-UAT-001 already exists | G10: 1. Go to Lots → New Lot 2. Enter lot number: LOT-UAT-001 3. Fill other fields 4. Save | H10: Lot#: LOT-UAT-001 (duplicate) | I10: Error shown: 'Lot number already exists'; lot not created
A11: TC-LOT-003 | B11: Lot Management | C11: High | D11: Positive | E11: View devices in lot | F11: Lot LOT-TEST-001 exists with devices | G11: 1. Go to Lots list 2. Click on LOT-TEST-001 3. View device list | H11: LOT-TEST-001 (seeded data) | I11: Device list shows all devices in the lot with barcode, stage, grade, brand, model
A12: TC-LOT-004 | B12: Lot Management | C12: Medium | D12: Positive | E12: Lot P&L calculation | F12: Lot has sold devices and spare parts consumption | G12: 1. Go to Dashboard 2. View Lot P&L table | H12: Seeded lots with sales and parts consumption | I12: P&L shows: Buying Price, Spare Parts Cost, Revenue, Gross Profit, Gross Margin % per lot
A13: TC-IQC-001 | B13: IQC | C13: Critical | D13: Positive | E13: Register new device with all fields | F13: IQC Inspector logged in; lot LOT-UAT-001 exists | G13: 1. Go to IQC → Register Device 2. Fill all 23 fields 3. Submit | H13: Barcode: OXY-UAT-00001 | Lot: LOT-UAT-001 | Brand: HP | Model: EliteBook 840 G6 | CPU: Intel i5-8250U | RAM: 8 | SSD: 256 | Type: SSD | Battery: 78 | Grade: B | Floor: Floor 1 | I13: Device registered; appears in IQC list; stage = IQC; all fields saved correctly
... A61: TC-BULK-004 | B61: Bulk Upload | C61: Critical | D61: Positive | E61: Upload valid devices CSV | F61: Lot LOT-UAT-001 exists; valid devices CSV prepared | G61: 1. Go to Bulk Upload → Devices 2. Upload CSV with 5 new device records | H61: 5 device rows with valid barcodes and LOT-UAT-001 | I61: 5 devices created at IQC stage; all appear in IQC list
A62: TC-BULK-005 | B62: Bulk Upload | C62: High | D62: Negative | E62: Upload devices CSV with non-existent lot | G62: 1. Upload devices CSV where lot_number does not exist in system | H62: lot_number: LOT-DOES-NOT-EXIST | I62: Rows with invalid lot fail; error report shows 'Lot not found'; valid rows still imported
A63: TC-BULK-006 | B63: Bulk Upload | C63: High | D63: Positive | E63: Upload valid spare parts CSV | G63: 1. Go to Bulk Upload → Spare Parts 2. Upload CSV with 3 new parts | H63: 3 part rows with unique part codes | I63: 3 parts created; appear in spare parts catalogue
A64: TC-MASTER-001 | B64: Master Data | C64: High | D64: Positive | E64: Add new brand to master data | F64: Admin logged in | G64: 1. Go to Admin → Master Data 2. Category: brand 3. Value: Samsung 4. Click Add | H64: Category: brand | Value: Samsung | I64: Samsung added to brand list; appears in IQC form brand dropdown immediately
A65: TC-MASTER-002 | B65: Master Data | C65: High | D65: Positive | E65: Disable a master data value | F65: Admin logged in; value exists | G65: 1. Go to Master Data 2. Find a value 3. Click Disable (toggle) | H65: Any active master data value | I65: Value marked inactive; no longer appears in form dropdowns; still visible in admin with 'disabled' indicator
A66: TC-MASTER-003 | B66: Master Data | C66: Medium | D66: Positive | E66: Delete a master data value | F66: Admin logged in; value exists and is not in use | G66: 1. Go to Master Data 2. Click Delete on an unused value 3. Confirm | H66: Unused master data value | I66: Value permanently removed from master data table
A67: TC-MASTER-004 | B67: Master Data | C67: Medium | D67: Negative | E67: Duplicate master data value rejected | F67: Brand 'HP' already exists | G67: 1. Go to Master Data 2. Add brand: HP | H67: Category: brand | Value: HP (duplicate) | I67: Error shown: 'Value already exists in this category'; not added
A68: TC-ADMIN-001 | B68: Admin / Users | C68: Critical | D68: Positive | E68: Create new user | F68: Admin logged in | G68: 1. Go to Admin → Users → New User 2. Fill all fields 3. Save | H68: Username: testeng | Full Name: Test Engineer | Role: l1_engineer | Password: Test@5678 | I68: User created; appears in user list; can login with new credentials
A69: TC-ADMIN-002 | B69: Admin / Users | C69: High | D69: Positive | E69: Edit user role | F69: Admin logged in; user testeng exists | G69: 1. Go to Admin → Users 2. Edit testeng 3. Change role to l2_engineer 4. Save | H69: New role: l2_engineer | I69: Role updated; user now has l2 access; old l1 routes denied
A70: TC-ADMIN-003 | B70: Admin / Users | C70: High | D70: Positive | E70: Deactivate user | F70: Admin logged in; user testeng active | G70: 1. Go to Admin → Users 2. Deactivate testeng | H70: User: testeng | I70: User status = inactive; testeng cannot login; marked as inactive in user list
A71: TC-ADMIN-004 | B71: Admin / Users | C71: High | D71: Positive | E71: Reactivate user | F71: User testeng is inactive | G71: 1. Go to Admin → Users 2. Re-activate testeng | H71: User: testeng (inactive) | I71: User status = active; testeng can login again
A72: TC-ADMIN-005 | B72: Admin / Users | C72: Medium | D72: Positive | E72: Login audit log records events | F72: Any user logs in and out | G72: 1. Login as salesexec 2. Logout 3. Admin checks login logs | H72: user: salesexec | I72: Login and logout events recorded with: username, action, IP address, timestamp
A73: TC-RPT-001 | B73: Reports & Export | C73: High | D73: Positive | E73: Export devices CSV | F73: Devices exist in system | G73: 1. Go to Reports 2. Click Export Devices CSV | H73: All devices in system | I73: CSV downloaded with columns: Barcode, Lot, Brand, Model, CPU, RAM, Storage, Grade, Stage, Floor
A74: TC-RPT-002 | B74: Reports & Export | C74: High | D74: Positive | E74: Export sales CSV | F74: Sales records exist | G74: 1. Go to Reports 2. Export Sales CSV | H74: Seeded 25 sales | I74: CSV with: Sale#, Barcode, Customer, Phone, Sale Price, Payment Mode, Date, Sold By
A75: TC-RPT-003 | B75: Reports & Export | C75: High | D75: Positive | E75: Export spare parts consumption CSV | F75: Consumption records exist | G75: 1. Go to Reports 2. Export Consumption CSV | H75: Seeded consumption data | I75: CSV with: Device, Part, Category, Qty, Unit Cost, Total Cost, Stage, Used By, Date
... A81: TC-SEC-005 | B81: Security & Access | C81: Medium | D81: Security | E81: Session expires after inactivity | F81: User logged in | G81: 1. Login 2. Wait 20 minutes without activity 3. Try to access a page | H81: JWT access token expires after 15 min | I81: Either auto-refreshed via refresh token, or redirected to login

Sheet 📊 Execution Tracker
A1: TC ID | B1: Module | C1: Priority | D1: Test Scenario | E1: Executed By | F1: Execution Date | G1: Pass / Fail | H1: Defect Ref | I1: Remarks
A2: TC-AUTH-001 | B2: Authentication | C2: Critical | D2: Valid admin login
A3: TC-AUTH-002 | B3: Authentication | C3: Critical | D3: Invalid password login
A4: TC-AUTH-003 | B4: Authentication | C4: Critical | D4: Non-existent user login
A5: TC-AUTH-004 | B5: Authentication | C5: High | D5: Deactivated user cannot login
A6: TC-AUTH-005 | B6: Authentication | C6: High | D6: Logout clears session
A7: TC-AUTH-006 | B7: Authentication | C7: High | D7: Role-based page access — Sales cannot access Admin
A8: TC-AUTH-007 | B8: Authentication | C8: High | D8: Role-based access — IQC cannot access Sales
A9: TC-LOT-001 | B9: Lot Management | C9: Critical | D9: Create new lot
A10: TC-LOT-002 | B10: Lot Management | C10: High | D10: Duplicate lot number rejected
A11: TC-LOT-003 | B11: Lot Management | C11: High | D11: View devices in lot
A12: TC-LOT-004 | B12: Lot Management | C12: Medium | D12: Lot P&L calculation
A13: TC-IQC-001 | B13: IQC | C13: Critical | D13: Register new device with all fields
... A81: TC-SEC-005 | B81: Security & Access | C81: Medium | D81: Session expires after inactivity

Sheet 📈 Test Summary
A2: OxyPC IMS — UAT Execution Summary
A4: Metric | D4: Count | F4: Formula Reference
A5: Total Test Cases | D5: =80
A6: Pass | D6: =COUNTIF('📊 Execution Tracker'!G2:G81,"Pass") | F6: COUNTIF('📊 Execution Tracker'!G:G,"Pass")
A7: Fail | D7: =COUNTIF('📊 Execution Tracker'!G2:G81,"Fail") | F7: COUNTIF('📊 Execution Tracker'!G:G,"Fail")
A8: Blocked | D8: =COUNTIF('📊 Execution Tracker'!G2:G81,"Blocked") | F8: COUNTIF('📊 Execution Tracker'!G:G,"Blocked")
A9: Not Tested | D9: =COUNTIF('📊 Execution Tracker'!G2:G81,"Not Tested") | F9: COUNTIF('📊 Execution Tracker'!G:G,"Not Tested")
A10: Not Applicable (N/A) | D10: =COUNTIF('📊 Execution Tracker'!G2:G81,"N/A") | F10: COUNTIF('📊 Execution Tracker'!G:G,"N/A")
A11: Executed | D11: =B6+B7+B8 | F11: Pass + Fail + Blocked
A12: Pass Rate % | D12: =IFERROR(B6/B11*100,0) | F12: (Pass / Executed) x 100
A13: Execution Rate % | D13: =IFERROR(B11/B5*100,0) | F13: (Executed / Total) x 100
A15: By Priority
A16: Critical | D16: =COUNTIF('📊 Execution Tracker'!C2:C81,"Critical")
A17: High | D17: =COUNTIF('📊 Execution Tracker'!C2:C81,"High")
A18: Medium | D18: =COUNTIF('📊 Execution Tracker'!C2:C81,"Medium")
A19: Low | D19: =COUNTIF('📊 Execution Tracker'!C2:C81,"Low")
A22: By Module
A23: Authentication | D23: 7 | F23: =COUNTIFS('📊 Execution Tracker'!B2:B81,"Authentication",'📊 Execution Tracker'!G2:G81,"Pass")
A24: Lot Management | D24: 4 | F24: =COUNTIFS('📊 Execution Tracker'!B2:B81,"Lot Management",'📊 Execution Tracker'!G2:G81,"Pass")
A25: IQC | D25: 7 | F25: =COUNTIFS('📊 Execution Tracker'!B2:B81,"IQC",'📊 Execution Tracker'!G2:G81,"Pass")
A26: Stock In | D26: 3 | F26: =COUNTIFS('📊 Execution Tracker'!B2:B81,"Stock In",'📊 Execution Tracker'!G2:G81,"Pass")
A27: L1 Repair | D27: 4 | F27: =COUNTIFS('📊 Execution Tracker'!B2:B81,"L1 Repair",'📊 Execution Tracker'!G2:G81,"Pass")
A28: L2 Repair | D28: 2 | F28: =COUNTIFS('📊 Execution Tracker'!B2:B81,"L2 Repair",'📊 Execution Tracker'!G2:G81,"Pass")
A29: L3 Repair | D29: 1 | F29: =COUNTIFS('📊 Execution Tracker'!B2:B81,"L3 Repair",'📊 Execution Tracker'!G2:G81,"Pass")
A30: QC Check | D30: 5 | F30: =COUNTIFS('📊 Execution Tracker'!B2:B81,"QC Check",'📊 Execution Tracker'!G2:G81,"Pass")
A31: Cosmetic Pipeline | D31: 5 | F31: =COUNTIFS('📊 Execution Tracker'!B2:B81,"Cosmetic Pipeline",'📊 Execution Tracker'!G2:G81,"Pass")
A32: Sales | D32: 4 | F32: =COUNTIFS('📊 Execution Tracker'!B2:B81,"Sales",'📊 Execution Tracker'!G2:G81,"Pass")
A33: Returns | D33: 3 | F33: =COUNTIFS('📊 Execution Tracker'!B2:B81,"Returns",'📊 Execution Tracker'!G2:G81,"Pass")
A34: Spare Parts | D34: 5 | F34: =COUNTIFS('📊 Execution Tracker'!B2:B81,"Spare Parts",'📊 Execution Tracker'!G2:G81,"Pass")
A35: RAM Tracking | D35: 3 | F35: =COUNTIFS('📊 Execution Tracker'!B2:B81,"RAM Tracking",'📊 Execution Tracker'!G2:G81,"Pass")
A36: Dashboard | D36: 3 | F36: =COUNTIFS('📊 Execution Tracker'!B2:B81,"Dashboard",'📊 Execution Tracker'!G2:G81,"Pass")
A37: Bulk Upload | D37: 6 | F37: =COUNTIFS('📊 Execution Tracker'!B2:B81,"Bulk Upload",'📊 Execution Tracker'!G2:G81,"Pass")
A38: Master Data | D38: 4 | F38: =COUNTIFS('📊 Execution Tracker'!B2:B81,"Master Data",'📊 Execution Tracker'!G2:G81,"Pass")
A39: Admin / Users | D39: 5 | F39: =COUNTIFS('📊 Execution Tracker'!B2:B81,"Admin / Users",'📊 Execution Tracker'!G2:G81,"Pass")
A40: Reports & Export | D40: 4 | F40: =COUNTIFS('📊 Execution Tracker'!B2:B81,"Reports & Export",'📊 Execution Tracker'!G2:G81,"Pass")
A41: Security & Access | D41: 5 | F41: =COUNTIFS('📊 Execution Tracker'!B2:B81,"Security & Access",'📊 Execution Tracker'!G2:G81,"Pass")

Sheet 📦 Test Data
A1: Category | B1: Field | C1: Test Value | D1: Notes
A2: User — Admin | B2: Username | C2: admin | D2: Default admin created by setup_db.py
A3: User — Admin | B3: Password | C3: Admin@1234 | D3: Change on first production use
A4: User — IQC | B4: Username | C4: iqc1 | D4: Seeded by seed_dummy_data.py
A5: User — IQC | B5: Password | C5: Test@1234 | D5: All seeded users same password
A6: User — L1 | B6: Username | C6: l1eng | D6: L1 Engineer role
A7: User — L2 | B7: Username | C7: l2eng | D7: L2 Engineer role
A8: User — QC | B8: Username | C8: qcinsp | D8: QC Inspector role
A9: User — Sales | B9: Username | C9: salesexec | D9: Sales Executive role
A10: User — Inventory | B10: Username | C10: invmgr | D10: Inventory Manager role
A11: User — Spare Parts | B11: Username | C11: spares1 | D11: Spare Parts Manager role
A12: Lot | B12: Lot Number | C12: LOT-UAT-001 | D12: Manual UAT test lot
... A16: Lot | B16: Purchase Date | C16: 2026-03-15 | D16: YYYY-MM-DD format
A17: Lot | B17: Invoice Number | C17: INV-UAT-2026-001
A18: Device | B18: Barcode | C18: OXY-UAT-00001 | D18: First UAT test device
A19: Device | B19: Barcode (2) | C19: OXY-UAT-00002 | D19: Second UAT test device (minimal fields)
A20: Device | B20: Brand | C20: HP | D20: From master data
A21: Device | B21: Model | C21: EliteBook 840 G6
A22: Device | B22: CPU | C22: Intel Core i5-8250U
A23: Device | B23: Generation | C23: 8th Gen
A24: Device | B24: RAM (GB) | C24: 8
A25: Device | B25: SSD (GB) | C25: 256
A26: Device | B26: Storage Type | C26: SSD
A27: Device | B27: Screen Size | C27: 14.0 FHD
A28: Device | B28: Battery Health % | C28: 78
A29: Device | B29: Grade | C29: B | D29: A/B/C/D/Scrap
A30: Device | B30: Floor | C30: Floor 1
A31: Device | B31: BIOS Password | C31: No | D31: yes/no
A32: Sale | B32: Sale Number | C32: SALE-UAT-001
A33: Sale | B33: Sale Price | C33: 25000 | D33: INR
A34: Sale | B34: Customer Name | C34: Rahul Sharma
A35: Sale | B35: Customer Phone | C35: 9876543210 | D35: 10-digit
A36: Sale | B36: Payment Mode | C36: UPI | D36: Cash/UPI/Card/Credit/Cheque
A37: Sale | B37: Invoice Number | C37: SINV-UAT-001
A38: Spare Part | B38: Part Code | C38: RAM-DDR4-16G
A39: Spare Part | B39: Name | C39: DDR4 16GB RAM
A40: Spare Part | B40: Category | C40: RAM
A41: Spare Part | B41: Unit Price | C41: 2500 | D41: INR
A42: Spare Part | B42: Qty in Stock | C42: 5
A43: Spare Part | B43: Min Stock Alert | C43: 2
...

Sheet 🐛 Defect Log
A1: Defect ID | B1: TC ID | C1: Module | D1: Defect Title | E1: Description / Steps to Reproduce | F1: Severity | G1: Priority | H1: Found By | I1: Date Found | J1: Screenshot/Attachment | K1: Assigned To | L1: Status | M1: Fixed Date | N1: Resolution Notes
A2: BUG-0001 | L2: Open
A3: BUG-0002 | L3: Open
A4: BUG-0003 | L4: Open
A5: BUG-0004 | L5: Open
A6: BUG-0005 | L6: Open

Sheet 01 — Auth
A1: OxyPC UAT — 01 — Auth
A2: TC ID | B2: Module | C2: Priority | D2: Test Type | E2: Test Scenario | F2: Pre-Conditions | G2: Test Steps | H2: Test Data | I2: Expected Result | J2: Actual Result | K2: Pass / Fail | L2: Remarks
A3: TC-AUTH-001 | B3: Authentication | C3: Critical | D3: Positive | E3: Valid admin login | F3: Admin user exists; server running | G3: 1. Navigate to http://<server>/ 2. Enter username: admin 3. Enter password: Admin@1234 4. Click Login | H3: user: admin | pwd: Admin@1234 | I3: Dashboard loads; sidebar shows all modules; user name visible in header
A4: TC-AUTH-002 | B4: Authentication | C4: Critical | D4: Negative | E4: Invalid password login | F4: Server running | G4: 1. Navigate to login page 2. Enter username: admin 3. Enter incorrect password: wrong123 4. Click Login | H4: user: admin | pwd: wrong123 | I4: Error message: 'Invalid credentials'; user stays on login page; no session created
A5: TC-AUTH-003 | B5: Authentication | C5: Critical | D5: Negative | E5: Non-existent user login | F5: Server running | G5: 1. Navigate to login page 2. Enter username: nobody 3. Enter any password 4. Click Login | H5: user: nobody | pwd: anything | I5: Error message shown; no access granted
A6: TC-AUTH-004 | B6: Authentication | C6: High | D6: Negative | E6: Deactivated user cannot login | F6: User 'testuser' exists with status=inactive | G6: 1. Admin deactivates a user 2. Attempt login with that user's credentials | H6: Deactivated user credentials | I6: Login rejected with 'Account inactive' or similar message
A7: TC-AUTH-005 | B7: Authentication | C7: High | D7: Positive | E7: Logout clears session | F7: User is logged in | G7: 1. Login as any user 2. Click Logout 3. Press browser Back button 4. Try to access /dashboard | H7: Any valid user | I7: User is redirected to login page; session cookie cleared
A8: TC-AUTH-006 | B8: Authentication | C8: High | D8: Security | E8: Role-based page access — Sales cannot access Admin | F8: User with Sales role is logged in | G8: 1. Login as salesexec 2. Manually navigate to http://<server>/admin | H8: user: salesexec | pwd: Test@1234 | I8: 403 Forbidden or redirect to login page; Admin module not accessible
A9: TC-AUTH-007 | B9: Authentication | C9: High | D9: Security | E9: Role-based access — IQC cannot access Sales | F9: User with IQC role is logged in | G9: 1. Login as iqc1 2. Navigate to /sales | H9: user: iqc1 | pwd: Test@1234 | I9: 403 error or redirect; IQC user cannot access Sales module

Sheet 02 — Lot Mgmt
A1: OxyPC UAT — 02 — Lot Mgmt
A2: TC ID | B2: Module | C2: Priority | D2: Test Type | E2: Test Scenario | F2: Pre-Conditions | G2: Test Steps | H2: Test Data | I2: Expected Result | J2: Actual Result | K2: Pass / Fail | L2: Remarks
A3: TC-LOT-001 | B3: Lot Management | C3: Critical | D3: Positive | E3: Create new lot | F3: Admin or Inventory Manager logged in | G3: 1. Go to Lots → New Lot 2. Fill all fields 3. Click Save | H3: Lot#: LOT-UAT-001 | Supplier: ABC Traders | Price: 85000 | Qty: 10 | Date: 2026-03-15 | Inv#: INV-UAT-001 | I3: Lot created; appears in lot list with correct details; lot count increments by 1
A4: TC-LOT-002 | B4: Lot Management | C4: High | D4: Negative | E4: Duplicate lot number rejected | F4: Lot LOT-UAT-001 already exists | G4: 1. Go to Lots → New Lot 2. Enter lot number: LOT-UAT-001 3. Fill other fields 4. Save | H4: Lot#: LOT-UAT-001 (duplicate) | I4: Error shown: 'Lot number already exists'; lot not created
A5: TC-LOT-003 | B5: Lot Management | C5: High | D5: Positive | E5: View devices in lot | F5: Lot LOT-TEST-001 exists with devices | G5: 1. Go to Lots list 2. Click on LOT-TEST-001 3. View device list | H5: LOT-TEST-001 (seeded data) | I5: Device list shows all devices in the lot with barcode, stage, grade, brand, model
A6: TC-LOT-004 | B6: Lot Management | C6: Medium | D6: Positive | E6: Lot P&L calculation | F6: Lot has sold devices and spare parts consumption | G6: 1. Go to Dashboard 2. View Lot P&L table | H6: Seeded lots with sales and parts consumption | I6: P&L shows: Buying Price, Spare Parts Cost, Revenue, Gross Profit, Gross Margin % per lot

Sheet 03 — IQC
A1: OxyPC UAT — 03 — IQC
A2: TC ID | B2: Module | C2: Priority | D2: Test Type | E2: Test Scenario | F2: Pre-Conditions | G2: Test Steps | H2: Test Data | I2: Expected Result | J2: Actual Result | K2: Pass / Fail | L2: Remarks
A3: TC-IQC-001 | B3: IQC | C3: Critical | D3: Positive | E3: Register new device with all fields | F3: IQC Inspector logged in; lot LOT-UAT-001 exists | G3: 1. Go to IQC → Register Device 2. Fill all 23 fields 3. Submit | H3: Barcode: OXY-UAT-00001 | Lot: LOT-UAT-001 | Brand: HP | Model: EliteBook 840 G6 | CPU: Intel i5-8250U | RAM: 8 | SSD: 256 | Type: SSD | Battery: 78 | Grade: B | Floor: Floor 1 | I3: Device registered; appears in IQC list; stage = IQC; all fields saved correctly
A4: TC-IQC-002 | B4: IQC | C4: Critical | D4: Negative | E4: Duplicate barcode rejected | F4: Device OXY-UAT-00001 already registered | G4: 1. Go to IQC → Register Device 2. Enter barcode: OXY-UAT-00001 3. Fill other fields 4. Submit | H4: Barcode: OXY-UAT-00001 (duplicate) | I4: Error shown: 'Barcode already exists'; device not created
A5: TC-IQC-003 | B5: IQC | C5: High | D5: Positive | E5: Barcode scan auto-fills existing device | F5: Device OXY-TEST-00001 exists; IQC form open | G5: 1. Scan barcode OXY-TEST-00001 into barcode field 2. Observe auto-fill | H5: Barcode: OXY-TEST-00001 | I5: All known fields auto-populated: brand, model, RAM, storage, grade, lot
A6: TC-IQC-004 | B6: IQC | C6: High | D6: Positive | E6: Register device with minimum required fields only | F6: IQC Inspector logged in; lot exists | G6: 1. Go to IQC → Register Device 2. Enter only barcode and lot 3. Submit | H6: Barcode: OXY-UAT-00002 | Lot: LOT-UAT-001 | I6: Device registered with barcode and lot; all optional fields null; stage = IQC
A7: TC-IQC-005 | B7: IQC | C7: High | D7: Positive | E7: BIOS password flagged at IQC | F7: IQC Inspector logged in | G7: 1. Register new device 2. Tick the 'BIOS Password' checkbox 3. Submit | H7: BIOS Password: Yes (ticked) | I7: Device record shows bios_password = True; flag visible in device detail
A8: TC-IQC-006 | B8: IQC | C8: Medium | D8: Positive | E8: IQC list shows all pending devices | F8: Multiple devices in IQC stage exist | G8: 1. Go to IQC module 2. View list | H8: Seeded data: 10 devices at IQC stage | I8: All IQC-stage devices listed; table sortable/searchable; device count shown
A9: TC-IQC-007 | B9: IQC | C9: Medium | D9: Positive | E9: Grade 'Scrap' can be assigned at IQC | F9: IQC Inspector logged in | G9: 1. Register new device 2. Select Grade = Scrap 3. Submit | H9: Grade: Scrap | Barcode: OXY-UAT-00003 | I9: Device registered with grade = Scrap; shows in IQC list

Sheet 04 — Stock In
A1: OxyPC UAT — 04 — Stock In
A2: TC ID | B2: Module | C2: Priority | D2: Test Type | E2: Test Scenario | F2: Pre-Conditions | G2: Test Steps | H2: Test Data | I2: Expected Result | J2: Actual Result | K2: Pass / Fail | L2: Remarks
A3: TC-STOCK-001 | B3: Stock In | C3: Critical | D3: Positive | E3: Move device from IQC to Stock In | F3: Device OXY-UAT-00001 in IQC stage; Inventory Manager logged in | G3: 1. Go to Stock In module 2. Find or scan OXY-UAT-00001 3. Confirm location 4. Click Move to Stock | H3: Barcode: OXY-UAT-00001 | Floor: Floor 1 | I3: Device stage updated to stock_in; stage movement recorded; device disappears from IQC list
A4: TC-STOCK-002 | B4: Stock In | C4: High | D4: Positive | E4: Stock In list shows only stock-in devices | F4: Devices in stock_in stage exist | G4: 1. Go to Stock In module 2. View list | H4: Seeded data: 10 devices at stock_in | I4: Only stock_in stage devices shown; correct device count
A5: TC-STOCK-003 | B5: Stock In | C5: Medium | D5: Negative | E5: Cannot move already-stocked device to stock again | F5: Device is already at stock_in stage | G5: 1. Attempt to move a stock_in device to stock_in again | H5: Device already in stock_in | I5: System prevents duplicate stage change; error or device absent from IQC list

Sheet 05 — Repair
A1: OxyPC UAT — 05 — Repair
A2: TC ID | B2: Module | C2: Priority | D2: Test Type | E2: Test Scenario | F2: Pre-Conditions | G2: Test Steps | H2: Test Data | I2: Expected Result | J2: Actual Result | K2: Pass / Fail | L2: Remarks
A3: TC-L1-001 | B3: L1 Repair | C3: Critical | D3: Positive | E3: Start L1 repair job | F3: Device in stock_in or l1 stage; L1 Engineer logged in | G3: 1. Go to L1 Repair 2. Scan device barcode 3. Enter issue description 4. Click Start Repair | H3: Barcode: OXY-TEST-00021 | Issue: RAM upgrade required | I3: Repair job created with status=in_progress; device stage = l1; appears in L1 list
A4: TC-L1-002 | B4: L1 Repair | C4: Critical | D4: Positive | E4: Complete L1 repair and advance to QC | F4: Device has open L1 repair job | G4: 1. Go to L1 Repair → Active Jobs 2. Click Complete on job 3. Enter resolution 4. Tick 'Move to next stage' 5. Submit | H4: Resolution: Upgraded RAM from 4GB to 8GB | Move to next: Yes | I4: Repair marked complete; device stage moves to qc_check; stage movement logged
A5: TC-L1-003 | B5: L1 Repair | C5: High | D5: Positive | E5: Complete repair WITHOUT advancing stage | F5: Device has open L1 repair job | G5: 1. Complete L1 repair job 2. Leave 'Move to next stage' UNCHECKED 3. Submit | H5: Move to next: No (unchecked) | I5: Repair marked complete; device STAYS at l1 stage; no stage movement to qc_check
A6: TC-L1-004 | B6: L1 Repair | C6: High | D6: Positive | E6: Log spare part consumption in L1 | F6: L1 Engineer logged in; spare part exists in stock | G6: 1. On device detail or repair form 2. Log consumption: part=RAM DDR4 8GB, qty=1 | H6: Part: RAM DDR4 8GB | Qty: 1 | Stage: L1 | I6: Consumption record created; spare part stock decremented by 1; cost linked to device
A7: TC-L2-001 | B7: L2 Repair | C7: Critical | D7: Positive | E7: Start and complete L2 repair job | F7: Device in l2 stage; L2 Engineer logged in | G7: 1. Go to L2 Repair 2. Start job for device in l2 queue 3. Enter issue + resolution 4. Complete and advance | H7: Issue: Screen crack | Resolution: Replaced 14-inch panel | Advance: Yes | I7: L2 job completed; device advances to qc_check; stage movement logged
A8: TC-L2-002 | B8: L2 Repair | C8: High | D8: Positive | E8: L2 engineer can log spare parts | F8: L2 Engineer logged in; screen panel in stock | G8: 1. Log consumption of 14-inch FHD panel for l2 device | H8: Part: 14-inch FHD IPS Panel | Qty: 1 | I8: Consumption logged; stock decremented; cost linked to device
A9: TC-L3-001 | B9: L3 Repair | C9: High | D9: Positive | E9: Start and complete L3 repair | F9: Device in l3 stage; L3 Engineer logged in | G9: 1. Start L3 job 2. Complete with resolution 3. Advance to QC | H9: Issue: No POST | Resolution: Reflowed southbridge chip | I9: L3 job completed; device to qc_check

Sheet 06 — QC Check
A1: OxyPC UAT — 06 — QC Check
A2: TC ID | B2: Module | C2: Priority | D2: Test Type | E2: Test Scenario | F2: Pre-Conditions | G2: Test Steps | H2: Test Data | I2: Expected Result | J2: Actual Result | K2: Pass / Fail | L2: Remarks
A3: TC-QC-001 | B3: QC Check | C3: Critical | D3: Positive | E3: QC Pass — device moves to Ready to Sale | F3: Device in qc_check stage; QC Inspector logged in | G3: 1. Go to QC Check list 2. Click QC on device OXY-TEST-00041 3. Select Result: Pass 4. Set Grade: B 5. Submit | H3: Barcode: OXY-TEST-00041 | Result: Pass | Grade: B | I3: QC check record created; device stage = ready_to_sale; device appears in Sales list
A4: TC-QC-002 | B4: QC Check | C4: Critical | D4: Positive | E4: QC Fail — device returned to repair | F4: Device in qc_check stage; QC Inspector logged in | G4: 1. Go to QC Check 2. Select Result: Fail 3. Enter issues found 4. Submit | H4: Result: Fail | Issues: Keyboard keys not responding | I4: QC fail recorded; device stage stays at qc_check or moves back to l1/l2 queue
A5: TC-QC-003 | B5: QC Check | C5: Critical | D5: Positive | E5: QC Scrap — device marked as scrapped | F5: Device in qc_check stage | G5: 1. Go to QC Check 2. Select Grade: Scrap 3. Result: Fail 4. Submit | H5: Grade: Scrap | Result: Fail | I5: Device stage = scrapped; device removed from active pipeline; scrap record saved
A6: TC-QC-004 | B6: QC Check | C6: High | D6: Positive | E6: Send QC-passed device to Cosmetic Pipeline | F6: Device in qc_check stage | G6: 1. In QC list, click 'Cosmetic' button for device 2. Confirm | H6: Barcode: OXY-TEST-00042 | I6: Device stage = cleaning; appears in Cosmetic Pipeline → Cleaning list
A7: TC-QC-005 | B7: QC Check | C7: Medium | D7: Positive | E7: QC list shows CPU and grade columns | F7: Devices in qc_check stage | G7: 1. Go to QC Check list 2. Observe columns | H7: Seeded data | I7: Table shows: Barcode, Lot, Brand, Model, CPU, RAM, Storage, Grade, Actions (QC + Cosmetic buttons)

Sheet 07 — Cosmetic
A1: OxyPC UAT — 07 — Cosmetic
A2: TC ID | B2: Module | C2: Priority | D2: Test Type | E2: Test Scenario | F2: Pre-Conditions | G2: Test Steps | H2: Test Data | I2: Expected Result | J2: Actual Result | K2: Pass / Fail | L2: Remarks
A3: TC-COS-001 | B3: Cosmetic Pipeline | C3: Critical | D3: Positive | E3: Cosmetic dashboard shows all 6 stages | F3: Devices exist in various cosmetic stages | G3: 1. Go to Cosmetic → Pipeline Dashboard 2. Observe all stage cards | H3: Seeded cosmetic devices | I3: Dashboard shows 6 stage cards: Cleaning, Dry Sanding, Masking, Painting, Water Sanding, Final QC with device counts
A4: TC-COS-002 | B4: Cosmetic Pipeline | C4: Critical | D4: Positive | E4: Advance device: Cleaning → Dry Sanding | F4: Device in cleaning stage; QC Inspector or Inv. Manager logged in | G4: 1. Go to Cosmetic → Cleaning 2. Scan device barcode in advance form 3. Click Advance | H4: Barcode: OXY-UAT-00001 | I4: Device stage = dry_sanding; stage movement logged; device removed from Cleaning list
A5: TC-COS-003 | B5: Cosmetic Pipeline | C5: Critical | D5: Positive | E5: Full cosmetic pipeline: Cleaning through Final QC | F5: Device in cleaning stage | G5: 1. Advance device through each stage sequentially 2. Cleaning → Dry Sanding → Masking → Painting → Water Sanding → Final QC | H5: Barcode: OXY-UAT-00001 | I5: Device progresses through all 6 stages; stage movements all recorded; at Final QC stage after 5 advances
A6: TC-COS-004 | B6: Cosmetic Pipeline | C6: Critical | D6: Positive | E6: Final QC advance → Ready to Sale | F6: Device in final_qc stage | G6: 1. Go to Cosmetic → Final QC 2. Advance device | H6: Barcode in final_qc stage | I6: Device stage = ready_to_sale; device appears in Sales → Ready to Sale list
A7: TC-COS-005 | B7: Cosmetic Pipeline | C7: High | D7: Positive | E7: Stage navigation tabs on stage page | F7: In any cosmetic stage page | G7: 1. Go to Cosmetic → Cleaning 2. Observe top nav tabs | H7: Any cosmetic stage | I7: Navigation tabs show all 6 stages; active stage highlighted; clicking tab navigates to that stage's list

Sheet 08 — Sales
A1: OxyPC UAT — 08 — Sales
A2: TC ID | B2: Module | C2: Priority | D2: Test Type | E2: Test Scenario | F2: Pre-Conditions | G2: Test Steps | H2: Test Data | I2: Expected Result | J2: Actual Result | K2: Pass / Fail | L2: Remarks
A3: TC-SALE-001 | B3: Sales | C3: Critical | D3: Positive | E3: Create a sale for ready device | F3: Device in ready_to_sale stage; Sales user logged in | G3: 1. Go to Sales → Ready to Sale 2. Click Sell on a device 3. Fill sale form 4. Submit | H3: Sale#: SALE-UAT-001 | Device: OXY-TEST-00051 | Price: 25000 | Customer: Rahul Sharma | Phone: 9876543210 | Payment: UPI | Inv: SINV-UAT-001 | I3: Sale created; device stage = sold; device removed from Ready to Sale list; revenue recorded
A4: TC-SALE-002 | B4: Sales | C4: High | D4: Positive | E4: Sales list shows all completed sales | F4: Sales records exist | G4: 1. Go to Sales → Sales List | H4: Seeded 25 sales records | I4: All sales listed with: Sale #, Device, Customer, Sale Price, Payment Mode, Date, Sold By
A5: TC-SALE-003 | B5: Sales | C5: High | D5: Positive | E5: All payment modes accepted | F5: Device in ready_to_sale | G5: 1. Create sale 2. Test each payment mode: Cash, UPI, Card, Credit, Cheque | H5: Payment Mode: Cash / UPI / Card / Credit / Cheque | I5: Each payment mode accepted; sale created successfully for each
A6: TC-SALE-004 | B6: Sales | C6: Medium | D6: Negative | E6: Cannot sell device not in ready_to_sale | F6: Device in l1 stage | G6: 1. Attempt to create sale for an l1-stage device | H6: Device in l1 stage | I6: Error shown or device not listed in Ready to Sale; sale cannot be created

Sheet 09 — Returns
A1: OxyPC UAT — 09 — Returns
A2: TC ID | B2: Module | C2: Priority | D2: Test Type | E2: Test Scenario | F2: Pre-Conditions | G2: Test Steps | H2: Test Data | I2: Expected Result | J2: Actual Result | K2: Pass / Fail | L2: Remarks
A3: TC-RET-001 | B3: Returns | C3: Critical | D3: Positive | E3: Process a return | F3: A sale exists; Sales user logged in | G3: 1. Go to Sales → Returns → New Return 2. Enter sale number or barcode 3. Fill reason and condition 4. Enter refund amount 5. Submit | H3: Sale: SALE-SEED-0001 | Reason: Not working | Condition: As Sold | Refund: 15000 | I3: Return record created; device stage = returned; refund amount saved
A4: TC-RET-002 | B4: Returns | C4: High | D4: Positive | E4: Returns list shows all returns | F4: Return records exist | G4: 1. Go to Sales → Returns | H4: Seeded 3 return records | I4: All returns listed: Return Date, Barcode, Device, Sale #, Sale Price, Refund, Reason, Condition, Processed By
A5: TC-RET-003 | B5: Returns | C5: Medium | D5: Positive | E5: Returned device can be re-routed to IQC | F5: Device in returned stage | G5: 1. Inventory Manager re-routes returned device to IQC or Stock In | H5: Returned device barcode | I5: Device stage moves from returned to iqc or stock_in; stage movement logged

Sheet 10 — Spare Parts
A1: OxyPC UAT — 10 — Spare Parts
A2: TC ID | B2: Module | C2: Priority | D2: Test Type | E2: Test Scenario | F2: Pre-Conditions | G2: Test Steps | H2: Test Data | I2: Expected Result | J2: Actual Result | K2: Pass / Fail | L2: Remarks
A3: TC-PARTS-001 | B3: Spare Parts | C3: Critical | D3: Positive | E3: Add new spare part | F3: Spare Parts Manager logged in | G3: 1. Go to Spare Parts → Add Part 2. Fill all fields 3. Save | H3: Code: RAM-DDR4-16G | Name: DDR4 16GB RAM | Category: RAM | Price: 2500 | Stock: 5 | Min Alert: 2 | Supplier: TechParts Ltd | I3: Part created; appears in catalogue; stock count shows 5
A4: TC-PARTS-002 | B4: Spare Parts | C4: Critical | D4: Positive | E4: Log purchase — stock increments | F4: Spare part exists; Spare Parts Manager logged in | G4: 1. Go to Spare Parts → Log Purchase 2. Select part RAM-DDR4-16G 3. Enter qty: 10 4. Submit | H4: Part: RAM-DDR4-16G | Qty: 10 | Unit Price: 2400 | Supplier: TechParts Ltd | I4: Purchase logged; part stock increments to 15; purchase record saved
A5: TC-PARTS-003 | B5: Spare Parts | C5: Critical | D5: Positive | E5: Log consumption — stock decrements | F5: Spare part in stock; repair job active | G5: 1. Go to Spare Parts → Log Consumption 2. Select part and device 3. Qty: 1 4. Submit | H5: Part: RAM-DDR4-16G | Device: OXY-TEST-00021 | Qty: 1 | Stage: L1 | I5: Consumption logged; stock decrements by 1; cost linked to device for P&L
A6: TC-PARTS-004 | B6: Spare Parts | C6: High | D6: Positive | E6: Low stock alert visible | F6: Part with qty_in_stock < min_stock_alert exists | G6: 1. Go to Spare Parts list 2. Observe low-stock flagging | H6: Part with stock=1, min_alert=5 | I6: Low-stock parts highlighted (red or warning indicator); visible on dashboard
A7: TC-PARTS-005 | B7: Spare Parts | C7: High | D7: Positive | E7: Edit spare part details | F7: Spare part exists | G7: 1. Go to Spare Parts list 2. Click Edit on a part 3. Update price and supplier 4. Save | H7: New price: 2800 | New supplier: Parts World | I7: Part updated; new values reflected in catalogue; part code unchanged (readonly)

Sheet 11 — RAM
A1: OxyPC UAT — 11 — RAM
A2: TC ID | B2: Module | C2: Priority | D2: Test Type | E2: Test Scenario | F2: Pre-Conditions | G2: Test Steps | H2: Test Data | I2: Expected Result | J2: Actual Result | K2: Pass / Fail | L2: Remarks
A3: TC-RAM-001 | B3: RAM Tracking | C3: High | D3: Positive | E3: Log RAM removal from device | F3: L1/L2 Engineer logged in; device in repair | G3: 1. Go to Spare Parts → RAM Tracking → Log Action 2. Action: Removed 3. Source device: OXY-TEST-00021 4. RAM: 4GB DDR4 5. Submit | H3: Action: removed | Device: OXY-TEST-00021 | RAM: 4GB | Type: DDR4 | I3: RAM removal logged; entry in ram_tracking table with action=removed
A4: TC-RAM-002 | B4: RAM Tracking | C4: High | D4: Positive | E4: Log RAM added to device | F4: RAM tracking — add | G4: 1. Action: Added 2. Destination device: OXY-TEST-00022 3. RAM: 8GB DDR4 | H4: Action: added | Device: OXY-TEST-00022 | RAM: 8GB | Type: DDR4 | I4: RAM add logged; device's RAM spec can be updated
A5: TC-RAM-003 | B5: RAM Tracking | C5: Medium | D5: Positive | E5: RAM tracking history viewable | F5: RAM tracking records exist | G5: 1. Go to Spare Parts → RAM Tracking 2. View log | H5: Seeded 5 RAM tracking entries | I5: All RAM actions listed: Action, Source Device, Destination Device, RAM GB, Type, By User, Date

Sheet 12 — Bulk Upload
A1: OxyPC UAT — 12 — Bulk Upload
A2: TC ID | B2: Module | C2: Priority | D2: Test Type | E2: Test Scenario | F2: Pre-Conditions | G2: Test Steps | H2: Test Data | I2: Expected Result | J2: Actual Result | K2: Pass / Fail | L2: Remarks
A3: TC-BULK-001 | B3: Bulk Upload | C3: High | D3: Positive | E3: Download lots CSV template | F3: Admin or Inv. Manager logged in | G3: 1. Go to Bulk Upload 2. Click Download Template — Lots | H3: Lots template download | I3: CSV file downloaded with correct headers: lot_number, supplier_name, buying_price, qty, purchase_date, invoice_no, notes
A4: TC-BULK-002 | B4: Bulk Upload | C4: Critical | D4: Positive | E4: Upload valid lots CSV | F4: Valid lots.csv prepared | G4: 1. Go to Bulk Upload 2. Select Lots section 3. Upload valid CSV with 3 new lots 4. Submit | H4: CSV: 3 rows with valid data; new lot numbers | I4: 3 lots created; success count = 3; error count = 0; lots appear in Lots list
A5: TC-BULK-003 | B5: Bulk Upload | C5: High | D5: Negative | E5: Bulk upload with duplicate lot number | F5: LOT-UAT-001 already exists | G5: 1. Upload CSV containing LOT-UAT-001 (existing) + 2 new lots | H5: CSV: 1 duplicate + 2 new | I5: 2 new lots created; duplicate row fails with error message; error count = 1
A6: TC-BULK-004 | B6: Bulk Upload | C6: Critical | D6: Positive | E6: Upload valid devices CSV | F6: Lot LOT-UAT-001 exists; valid devices CSV prepared | G6: 1. Go to Bulk Upload → Devices 2. Upload CSV with 5 new device records | H6: 5 device rows with valid barcodes and LOT-UAT-001 | I6: 5 devices created at IQC stage; all appear in IQC list
A7: TC-BULK-005 | B7: Bulk Upload | C7: High | D7: Negative | E7: Upload devices CSV with non-existent lot | G7: 1. Upload devices CSV where lot_number does not exist in system | H7: lot_number: LOT-DOES-NOT-EXIST | I7: Rows with invalid lot fail; error report shows 'Lot not found'; valid rows still imported
A8: TC-BULK-006 | B8: Bulk Upload | C8: High | D8: Positive | E8: Upload valid spare parts CSV | G8: 1. Go to Bulk Upload → Spare Parts 2. Upload CSV with 3 new parts | H8: 3 part rows with unique part codes | I8: 3 parts created; appear in spare parts catalogue

Sheet 13 — Master Data
A1: OxyPC UAT — 13 — Master Data
A2: TC ID | B2: Module | C2: Priority | D2: Test Type | E2: Test Scenario | F2: Pre-Conditions | G2: Test Steps | H2: Test Data | I2: Expected Result | J2: Actual Result | K2: Pass / Fail | L2: Remarks
A3: TC-MASTER-001 | B3: Master Data | C3: High | D3: Positive | E3: Add new brand to master data | F3: Admin logged in | G3: 1. Go to Admin → Master Data 2. Category: brand 3. Value: Samsung 4. Click Add | H3: Category: brand | Value: Samsung | I3: Samsung added to brand list; appears in IQC form brand dropdown immediately
A4: TC-MASTER-002 | B4: Master Data | C4: High | D4: Positive | E4: Disable a master data value | F4: Admin logged in; value exists | G4: 1. Go to Master Data 2. Find a value 3. Click Disable (toggle) | H4: Any active master data value | I4: Value marked inactive; no longer appears in form dropdowns; still visible in admin with 'disabled' indicator
A5: TC-MASTER-003 | B5: Master Data | C5: Medium | D5: Positive | E5: Delete a master data value | F5: Admin logged in; value exists and is not in use | G5: 1. Go to Master Data 2. Click Delete on an unused value 3. Confirm | H5: Unused master data value | I5: Value permanently removed from master data table
A6: TC-MASTER-004 | B6: Master Data | C6: Medium | D6: Negative | E6: Duplicate master data value rejected | F6: Brand 'HP' already exists | G6: 1. Go to Master Data 2. Add brand: HP | H6: Category: brand | Value: HP (duplicate) | I6: Error shown: 'Value already exists in this category'; not added

Sheet 14 — Admin
A1: OxyPC UAT — 14 — Admin
A2: TC ID | B2: Module | C2: Priority | D2: Test Type | E2: Test Scenario | F2: Pre-Conditions | G2: Test Steps | H2: Test Data | I2: Expected Result | J2: Actual Result | K2: Pass / Fail | L2: Remarks
A3: TC-ADMIN-001 | B3: Admin / Users | C3: Critical | D3: Positive | E3: Create new user | F3: Admin logged in | G3: 1. Go to Admin → Users → New User 2. Fill all fields 3. Save | H3: Username: testeng | Full Name: Test Engineer | Role: l1_engineer | Password: Test@5678 | I3: User created; appears in user list; can login with new credentials
A4: TC-ADMIN-002 | B4: Admin / Users | C4: High | D4: Positive | E4: Edit user role | F4: Admin logged in; user testeng exists | G4: 1. Go to Admin → Users 2. Edit testeng 3. Change role to l2_engineer 4. Save | H4: New role: l2_engineer | I4: Role updated; user now has l2 access; old l1 routes denied
A5: TC-ADMIN-003 | B5: Admin / Users | C5: High | D5: Positive | E5: Deactivate user | F5: Admin logged in; user testeng active | G5: 1. Go to Admin → Users 2. Deactivate testeng | H5: User: testeng | I5: User status = inactive; testeng cannot login; marked as inactive in user list
A6: TC-ADMIN-004 | B6: Admin / Users | C6: High | D6: Positive | E6: Reactivate user | F6: User testeng is inactive | G6: 1. Go to Admin → Users 2. Re-activate testeng | H6: User: testeng (inactive) | I6: User status = active; testeng can login again
A7: TC-ADMIN-005 | B7: Admin / Users | C7: Medium | D7: Positive | E7: Login audit log records events | F7: Any user logs in and out | G7: 1. Login as salesexec 2. Logout 3. Admin checks login logs | H7: user: salesexec | I7: Login and logout events recorded with: username, action, IP address, timestamp

Sheet 15 — Reports
A1: OxyPC UAT — 15 — Reports
A2: TC ID | B2: Module | C2: Priority | D2: Test Type | E2: Test Scenario | F2: Pre-Conditions | G2: Test Steps | H2: Test Data | I2: Expected Result | J2: Actual Result | K2: Pass / Fail | L2: Remarks
A3: TC-RPT-001 | B3: Reports & Export | C3: High | D3: Positive | E3: Export devices CSV | F3: Devices exist in system | G3: 1. Go to Reports 2. Click Export Devices CSV | H3: All devices in system | I3: CSV downloaded with columns: Barcode, Lot, Brand, Model, CPU, RAM, Storage, Grade, Stage, Floor
A4: TC-RPT-002 | B4: Reports & Export | C4: High | D4: Positive | E4: Export sales CSV | F4: Sales records exist | G4: 1. Go to Reports 2. Export Sales CSV | H4: Seeded 25 sales | I4: CSV with: Sale#, Barcode, Customer, Phone, Sale Price, Payment Mode, Date, Sold By
A5: TC-RPT-003 | B5: Reports & Export | C5: High | D5: Positive | E5: Export spare parts consumption CSV | F5: Consumption records exist | G5: 1. Go to Reports 2. Export Consumption CSV | H5: Seeded consumption data | I5: CSV with: Device, Part, Category, Qty, Unit Cost, Total Cost, Stage, Used By, Date
A6: TC-RPT-004 | B6: Reports & Export | C6: Medium | D6: Positive | E6: Export stage movements CSV | F6: Stage movements exist | G6: 1. Go to Reports 2. Export Movements CSV | H6: Stage movements audit trail | I6: CSV with: Device, From Stage, To Stage, Moved By, Moved At, Notes

Sheet 16 — Security
A1: OxyPC UAT — 16 — Security
A2: TC ID | B2: Module | C2: Priority | D2: Test Type | E2: Test Scenario | F2: Pre-Conditions | G2: Test Steps | H2: Test Data | I2: Expected Result | J2: Actual Result | K2: Pass / Fail | L2: Remarks
A3: TC-SEC-001 | B3: Security & Access | C3: Critical | D3: Security | E3: Direct URL access without authentication | F3: Not logged in | G3: 1. Close browser 2. Navigate directly to http://<server>/dashboard 3. Observe redirect | H3: No session cookie | I3: Redirected to login page; cannot access any protected page without authentication
A4: TC-SEC-002 | B4: Security & Access | C4: Critical | D4: Security | E4: L1 engineer cannot access Sales module | F4: L1 Engineer logged in | G4: 1. Login as l1eng 2. Navigate to /sales | H4: user: l1eng | pwd: Test@1234 | I4: 403 error or redirect; /sales page not accessible to L1 engineer
A5: TC-SEC-003 | B5: Security & Access | C5: High | D5: Security | E5: Spare Parts Manager cannot access Admin | F5: Spare Parts Manager logged in | G5: 1. Login as spares1 2. Navigate to /admin | H5: user: spares1 | pwd: Test@1234 | I5: 403 error or redirect; Admin page not accessible
A6: TC-SEC-004 | B6: Security & Access | C6: High | D6: Security | E6: Sales user cannot create lots | F6: Sales user logged in | G6: 1. Login as salesexec 2. Navigate to /lots/new | H6: user: salesexec | pwd: Test@1234 | I6: 403 error; Sales user cannot create or view lots
A7: TC-SEC-005 | B7: Security & Access | C7: Medium | D7: Security | E7: Session expires after inactivity | F7: User logged in | G7: 1. Login 2. Wait 20 minutes without activity 3. Try to access a page | H7: JWT access token expires after 15 min | I7: Either auto-refreshed via refresh token, or redirected to login
